Workbook
Name Slicer_Company_Name: #N/A
Name Slicer_Year: #N/A

Sheet Sources
A1: Sources and Bases of the DATA / Assumptions used in the Valuation
A3: S. No | B3: Details of Assumptions/Data Point | C3: Assumed Figure | D3: Remarks | E3: URL
A4: 1 | B4: Actual Financial Statement data for last 7 years | D4: Financial statements has been taken for the last seven years from capitaline database | E4: https://awsone.capitaline.com/index.html#/Company/Condensed/condensed?section=ProfitLoss
A5: 2 | B5: Revenue Growth | C5: 0.08
A6: 3 | B6: Tax Rate | C6: 0.2362 | D6: Cipla Annual Report 2025
A7: 4 | B7: Risk free Rate (Rf) | C7: 0.0667 | D7: 10-year Indian Government bond yield used as proxy for risk-free rate | E7: https://in.investing.com/rates-bonds/india-10-year-bond-yield-historical-data?utm_source
A8: 5 | B8: Market Risk (Rm) | C8: 0.1276313 | D8: Average long-term return of Indian stock market (NIFTY 50) used as market return
B9: Market Risk Premium (Rp= Rm-Rf) | C9: =C8-C7 -> 0.060931297 | D9: Market risk premium calculated as difference between market return and risk-free rate
A10: 6 | B10: Terminal Growth Rate | C10: 0.06 | D10: Terminal growth rate assumed based on long-term GDP growth and pharmaceutical industry growth | E10: https://data.worldbank.org/indicator/NY.GDP.MKTP.KD.ZG
A11: 7 | B11: Cipla Stock Data | D11: Historical stock price data used for Beta calculation | E11: https://www.bseindia.com/
A12: 8 | B12: NIFTY 50 data | D12: Market index data used for Beta calculation | E12: https://www.bseindia.com/
A13: 9 | B13: Current Market Price | C13: 1242.65 | D13: Latest market price from stock exchange | E13: https://awsone.capitaline.com/index.html#/Company/General/CompanyInfo

Sheet Company Overview
A1: CIPLA Limited.
A4: ABOUT THE COMPANY | D4: Segment
A5: Company Name | B5: Cipla Limited | D5: Segment | E5: Key Brands / Therapies | F5: Business Description
A6: Listing | B6: NSE / BSE | D6: Pharmaceuticals (India) | E6: Ciprobay, Asthalin, Foracort, Nexito, Ciplox, Rescof | F6: Branded prescription generics, trade generics, and consumer health products. Largest revenue segment; #3 in Indian Rx market. #1 in Respiratory therapy.
A7: Sector | B7: Healthcare | D7: North America (US) | E7: Generic inhalers, Albuterol, Revlimid (generic), Absorica | F7: Complex generics, inhalation products, and specialty pharma for the US market. Fastest-growing generic player; FY25 revenue of $934 million.
A8: Industry | B8: Pharmaceuticals & Generics | D8: South Africa / Emerging Markets | E8: Cipla Medpro, Cipla Quality Chemical Industries (CQCI) | F8: OTC, branded generics, and tender business. #3 private Rx market in South Africa. Strong presence in Africa and EMEU (Emerging Markets & Europe).
A9: Founded | B9: 1935 | D9: APIs (Active Pharm. Ingredients) | E9: Bulk APIs supplied to third parties and captive use | F9: Manufacture and supply of APIs globally. Supports cost control and supply chain integrity. India is the world's 3rd largest API producer.
A10: Headquarters | B10: Mumbai, India | D10: New Ventures / Digital Health | E10: Wellthy Therapeutics, Digital Breathe Free, Inzpera | F10: Digital therapeutics, telehealth, biosimilars, and specialty pipeline investments. Expansion into obesity (Semaglutide) and inhaled insulin (Afrezza).
A11: Promoter | B11: Hamied Family
A12: Market Cap | B12: Rs. 1.0 Trillion | D12: Growth Drivers – Cipla Limited
D13: Growth Driver | E13: Explanation | F13: Valuation Significance
A14: Cipla Limited represents a structurally strong play on India's branded generics and global respiratory franchise. Its #1 position in respiratory therapy, fast-growing US complex generics portfolio, and expanding South Africa/EMEU presence support durable revenue visibility. The company's investment in digital health and biosimilars provides future growth optionality. However, profitability is sensitive to US generic pricing, regulatory observations, and NPPA pricing controls in India. | D14: Respiratory Market Leadership | E14: Cipla holds #1 rank in India's respiratory therapy. Chronic COPD/asthma burden rising; inhalation CAGR ~9% to 2031. | F14: Supports pricing power, high-margin revenue mix, and competitive moat in complex device-led generics.
D15: US Complex Generics Scale-Up | E15: FY25 US revenue reached $934M (highest ever). Pipeline of injectables, inhalation, and specialty products. | F15: Drives earnings growth and margin expansion; $10B+ patent cliff opportunity by 2029.
D16: Premiumization in India Rx | E16: Chronic share rising (60%+ of India portfolio). Branded prescription growing ~12% YoY with price+mix uplift. | F16: Improves revenue quality and EBITDA margins; reduces cyclicality.
D17: Africa & EMEU Expansion | E17: South Africa private market growing 15-19% YoY; Africa provides tender + OTC revenue diversification. | F17: Adds geographic diversification; CQCI Africa is a long-term structural opportunity.
D18: Biosimilars & New Modalities | E18: Pipeline in semaglutide (GLP-1), oligonucleotides, inhaled insulin (Afrezza); digital therapeutics. | F18: Future growth optionality with high-barrier, high-margin pipeline.
D19: Jan Aushadhi / Trade Generics | E19: Government push for affordable medicines expands volume market; Cipla's trade generics growing double-digit. | F19: Volume growth buffer and rural market penetration.
D20: Omni-Channel & Digital Health | E20: Digital Breathe Free platform (5L+ downloads). E-pharmacy and telehealth integration. | F20: Expands addressable patient base; improves adherence and brand recall.
D21: Brand Equity & Regulatory Track Record | E21: 85%+ of physicians prescribe at least one Cipla product; 47 global manufacturing sites. | F21: Creates durable competitive advantages; supports entry into regulated markets like the US, EU.
D23: Economic Moat – Cipla Limited
A24: Economic Moat – Cipla Limited
A25: Cipla Limited possesses a strong economic moat anchored in three pillars: (1) Device-led inhalation leadership – Cipla's Rotahaler and respiratory franchise is the #1 in India and difficult to replicate, requiring device expertise alongside drug formulation. (2) Regulatory depth – with 47 manufacturing sites, US FDA approvals, and WHO GMP compliance, Cipla has built significant regulatory capital that serves as a durable entry barrier. (3) Brand trust in India and Africa – Cipla's 90-year legacy and Hamied family mission of affordable medicines has created deep physician loyalty (85%+ HCP coverage) and consumer trust. The company's net cash position of ~Rs. 10,369 crore (FY25) provides financial resilience and capacity for bolt-on acquisitions. Tata-like brand recall and public health credibility further reinforce competitive durability.

Sheet Industry Overview
B1: Industry Analysis – Key Insights
B2: Cipla Revenue Trend | C2: Cipla's consolidated revenue has grown from ~Rs. 9,774 Cr (FY15) to ~Rs. 28,400 Cr (FY25), representing a ~11% CAGR over a decade. Growth has been driven by three engines: India branded prescription (+10-12% annually), North America complex generics (now $934M annually), and South Africa/EMEU markets. The company crossed Rs. 25,000 Cr in FY24 – a milestone that confirms large-cap generics scale. Revenue quality has improved as Cipla's revenue mix shifts toward complex, high-margin products (inhalers, specialty generics, biosimilars).
B4: India Pharma Market & Organized Share | C4: India's pharma market grew from $20 Bn to $42 Bn over 2015-2025. Crucially, the organized segment's share has expanded from ~45% to ~60%, benefiting branded generics players like Cipla. Government schemes (Ayushman Bharat, PM Jan Aushadhi) have widened access while also constraining NPPA-regulated pricing. Cipla's India market share (~5.7%) has remained stable, reflecting both competitive market dynamics and Cipla's consistent outperformance in respiratory therapy.
B6: US Market & Complex Generics | C6: North America revenue has scaled from ~$320M (FY15) to $934M (FY25), driven by complex generic launches (Albuterol, Revlimid, specialty injectables). The US generic market faces structural pricing erosion in plain generics, but complex products (inhalers, injectables, modified-release) provide pricing stability. Cipla is positioned as a 'fastest-growing generic player' in the US. The upcoming $10B+ patent cliff (2026-29) offers incremental launch opportunities.
B8: Respiratory Market Leadership | C8: Cipla's respiratory franchise is its deepest moat. India's respiratory burden (37M+ asthma/COPD patients) and rising pollution-linked cases (274 days exceeding WHO limits in Delhi) structurally support double-digit inhaler market growth. Cipla's Rotahaler platform and Foracort brand franchise dominate. Globally, inhalation therapy markets are expanding at 9%+ CAGR, and Cipla's device expertise creates high barriers for new entrants – regulatory ANDA pathways for inhalers are complex and time-consuming.
B10: Across the study period, Cipla's industry positioning has strengthened materially. The company has successfully navigated the complexity of operating across four distinct markets (India, US, South Africa, EMEU) with differentiated product strategies in each. The shift toward complex generics, inhalation, and specialty pharma has improved revenue quality and margin resilience. Market share in India's organized sector has remained stable while organized sector share itself expands – a structural tailwind. The industry's long-term outlook is favorable: India projected to reach $120-130 Bn by 2030, global patent cliff of $10B+ by 2029, and biosimilar/GLP-1 new market creation. Collectively, Cipla's industry analysis supports durable mid-to-high single digit revenue growth with margin expansion driven by complex product mix.
A17: Year | B17: India Pharma Mkt (USD Bn) | C17: Cipla Revenue (Rs Cr) | D17: Cipla US Revenue (USD Mn) | E17: Organized Generics Share (%) | F17: Cipla India Mkt Share (%) | G17: Respiratory Market (Rs Cr)
A18: 2015 | B18: 20 | C18: 9774 | D18: 320 | E18: 45 | F18: 4.8 | G18: 8000 | I18: Over the period 2015 to 2025, the Indian pharmaceutical market shows strong expansion, growing from $20 billion to $42 billion, indicating a robust increase in healthcare demand and industry potential. Alongside this, Cipla demonstrates consistent and significant revenue growth, with its revenue rising from ₹9,774 crore to ₹28,400 crore, reflecting strong operational performance and market positioning. A key contributor to this growth is the company’s increasing presence in the US market, where revenue nearly tripled from $320 million to $934 million, highlighting its success in regulated and high-margin markets. The share of organized generics also increased from 45% to 60%, suggesting a structural shift in the industry that benefits established players like Cipla. Although Cipla’s India market share improved from 4.8% to 5.8%, the growth remains gradual, indicating intense competition in the domestic market. Additionally, the respiratory segment, which is Cipla’s core strength, expanded significantly from ₹8,000 crore to ₹21,000 crore, supporting its competitive advantage. Overall, the data reflects that Cipla is on a strong growth trajectory driven by global expansion and therapeutic specialization, while still facing competitive pressures in its home market.
A19: 2016 | B19: 21.5 | C19: 10938 | D19: 360 | E19: 47 | F19: 5 | G19: 8800
A20: 2017 | B20: 23 | C20: 12055 | D20: 380 | E20: 48 | F20: 5.1 | G20: 9500
A21: 2018 | B21: 25 | C21: 14273 | D21: 390 | E21: 50 | F21: 5.2 | G21: 10500
A22: 2019 | B22: 27 | C22: 16363 | D22: 400 | E22: 51 | F22: 5.3 | G22: 11500
A23: 2020 | B23: 24 | C23: 16779 | D23: 420 | E23: 52 | F23: 5.5 | G23: 13000
A24: 2021 | B24: 26.5 | C24: 19160 | D24: 520 | E24: 54 | F24: 5.6 | G24: 14500
A25: 2022 | B25: 30 | C25: 20038 | D25: 620 | E25: 56 | F25: 5.5 | G25: 16000
A26: 2023 | B26: 33 | C26: 22753 | D26: 720 | E26: 57 | F26: 5.6 | G26: 17500
A27: 2024 | B27: 38 | C27: 25774 | D27: 830 | E27: 58 | F27: 5.7 | G27: 19000
A28: 2025 | B28: 42 | C28: 28400 | D28: 934 | E28: 60 | F28: 5.8 | G28: 21000
A31: Year | B31: Cipla Rev Growth (%) | C31: India Pharma Mkt Growth (%) | D31: US Rev Growth (%) | E31: Org. Share Change (pp) | F31: Resp Mkt Growth (%)
A32: 2015 | B32: - | C32: - | D32: - | E32: - | F32: -
A33: 2016 | B33: 12 | C33: 7.5 | D33: 12.5 | E33: 2 | F33: 10
A34: 2017 | B34: 10 | C34: 7 | D34: 5.6 | E34: 1 | F34: 8
A35: 2018 | B35: 18 | C35: 8.7 | D35: 2.6 | E35: 2 | F35: 10.5
A36: 2019 | B36: 15 | C36: 8 | D36: 2.6 | E36: 1 | F36: 9.5
A37: 2020 | B37: 2 | C37: -11.1 | D37: 5 | E37: 1 | F37: 13
A38: 2021 | B38: 14 | C38: 10.4 | D38: 23.8 | E38: 2 | F38: 11.5
A39: 2022 | B39: 5 | C39: 13.2 | D39: 19.2 | E39: 2 | F39: 10.3
A40: 2023 | B40: 14 | C40: 10 | D40: 16.1 | E40: 1 | F40: 9.4
A41: 2024 | B41: 13 | C41: 15.2 | D41: 15.3 | E41: 1 | F41: 8.6
A42: 2025 | B42: 10 | C42: 10.5 | D42: 12.5 | E42: 2 | F42: 10.5

Sheet Raw Data
A1: CIPLA LIMITED – INCOME STATEMENT (Source: Capitaline) | J1: CIPLA LIMITED – BALANCE SHEET (Source: Capitaline)
A2: Particulars (INR Cr.) | B2: 2019 | C2: 2020 | D2: 2021 | E2: 2022 | F2: 2023 | G2: 2024 | H2: 2025 | J2: Particulars (INR Cr.) | K2: 2019 | L2: 2020 | M2: 2021 | N2: 2022 | O2: 2023 | P2: 2024 | Q2: 2025
A3: INCOME STATEMENT | J3: BALANCE SHEET
A5: Year | B5: 2019 | C5: 2020 | D5: 2021 | E5: 2022 | F5: 2023 | G5: 2024 | H5: 2025 | J5: Year | K5: 2019 | L5: 2020 | M5: 2021 | N5: 2022 | O5: 2023 | P5: 2024 | Q5: 2025
A6: INCOME : | J6: Shareholder's Funds
A7: Sales Turnover | B7: 12374.01 | C7: 12659.15 | D7: 11302.71 | E7: 13091.79 | F7: 14345.34 | G7: 16574.34 | H7: 19044.85 | J7: Share Capital | K7: 161.14 | L7: 161.25 | M7: 161.29 | N7: 161.36 | O7: 161.43 | P7: 161.47 | Q7: 161.52
A8: Net Sales | B8: 12374.01 | C8: 12659.15 | D8: 11302.71 | E8: 13091.79 | F8: 14345.34 | G8: 16574.34 | H8: 19044.85 | J8: Ordinary Capital | K8: 161.14 | L8: 161.25 | M8: 161.29 | N8: 161.36 | O8: 161.43 | P8: 161.47 | Q8: 161.52
A9: Other Income | B9: 577.52 | C9: 892.85 | D9: 653.91 | E9: 935.24 | F9: 826.2 | G9: 1433.72 | H9: 1279.38 | J9: Reserves and Surplus | K9: 15620.77 | L9: 17241.71 | M9: 19766.27 | N9: 22352.19 | O9: 24476.66 | P9: 27812.45 | Q9: 31937.72
A10: Dividend Income | B10: 241.5 | C10: 565.51 | D10: 0 | E10: 403.32 | F10: 14.92 | G10: 380.69 | H10: 99.27 | J10: Total Shareholder's Fund | K10: 15781.91 | L10: 17402.96 | M10: 19927.56 | N10: 22513.55 | O10: 24638.09 | P10: 27973.92 | Q10: 32099.24
A11: Interest Income | B11: 59.63 | C11: 60.91 | D11: 36.42 | E11: 72.89 | F11: 158.74 | G11: 293.82 | H11: 399.65 | J11: Non-Current Liabilities
A12: Profit on sale of Fixed Assets | B12: 0 | C12: 2.86 | D12: 3.48 | E12: 0.72 | F12: 11.02 | G12: 7.5 | H12: -1.85 | J12: Long-Term Borrowings | K12: 0 | L12: 0 | M12: 0 | N12: 0 | O12: 0 | P12: 0 | Q12: 0
A13: Profit on sale of investments | B13: 107.41 | C13: 114.02 | D13: 47.67 | E13: 64 | F13: 118.13 | G13: 43.47 | H13: 143.13 | J13: Lease Liabilities | K13: 0 | L13: 0 | M13: 29.46 | N13: 15.53 | O13: 35.53 | P13: 29.55 | Q13: 86.18
A14: Rent received | B14: 5.35 | C14: 9.16 | D14: 15.91 | E14: 12.6 | F14: 9.11 | G14: 14.16 | H14: 15.73 | J14: Deferred Tax Liabilities (Net) | K14: 42.84 | L14: 112.97 | M14: 104.91 | N14: 79.25 | O14: 36.13 | P14: 32.64 | Q14: 0
A15: Gain on Cancell. of Forward Contr/forex trans | B15: 20.38 | C15: 119.39 | D15: 44.13 | E15: 65.77 | F15: 92.59 | G15: 46.2 | H15: 5.6 | J15: Deferred Tax Liability | K15: 494.77 | L15: 353.62 | M15: 104.91 | N15: 313.69 | O15: 286.08 | P15: 243.71 | Q15: 0
A16: Refunds / Claims Received | B16: 4.58 | C16: 2.99 | D16: 1.38 | E16: 8.58 | F16: 16.84 | G16: 4.6 | H16: 14.52 | J16: Deferred Tax Assets | K16: 451.93 | L16: 240.65 | M16: 0 | N16: 234.44 | O16: 249.95 | P16: 211.07 | Q16: 0
A17: Income from Subsidiaries | B17: 0 | C17: 0.07 | D17: 0 | E17: 0 | F17: 0 | G17: 4.93 | H17: 0 | J17: Other Long Term Liabilities | K17: 117.86 | L17: 165.3 | M17: 113.9 | N17: 99.75 | O17: 105.25 | P17: 60.63 | Q17: 87.76
A18: Income from Investment Activities | B18: 19.11 | C18: -20.91 | D18: 10.12 | E18: 3.23 | F18: 13.89 | G18: 215.01 | H18: 237.02 | J18: Long-Term Provisions | K18: 108.12 | L18: 105.14 | M18: 95.97 | N18: 81.63 | O18: 81.73 | P18: 94.24 | Q18: 109.12
A19: Provision Written Back | B19: 19.11 | C19: 2.41 | D19: 0 | E19: 0 | F19: 0 | G19: 7.03 | H19: 5.5 | J19: Total Non Current Liabilities | K19: 268.82 | L19: 383.41 | M19: 344.24 | N19: 276.16 | O19: 258.64 | P19: 217.06 | Q19: 283.06
A20: Miscellaneous Income | B20: 19.11 | C20: 36.44 | D20: 494.8 | E20: 304.13 | F20: 390.96 | G20: 416.31 | H20: 360.81 | J20: Current Liabilities
A21: Stock Adjustments | B21: 19.11 | C21: 43.08 | D21: -6.41 | E21: 528.4 | F21: -194.32 | G21: -104.57 | H21: 229.87 | J21: Short-Term Borrowings | K21: 0 | L21: 6.06 | M21: 0 | N21: 0 | O21: 0 | P21: 0 | Q21: 0
A22: Total Income | B22: 19.11 | C22: 13595.08 | D22: 11950.21 | E22: 14555.43 | F22: 14977.22 | G22: 17903.49 | H22: 20554.1 | J22: Lease Liabilities | L22: 0 | M22: 29.46 | N22: 15.53 | O22: 35.53 | P22: 29.55 | Q22: 86.18
A23: EXPENDITURE : | J23: Trade Payables | K23: 1481.35 | L23: 1612.12 | M23: 1495.49 | N23: 1569.73 | O23: 1638.92 | P23: 1684.64 | Q23: 1883.71
A24: Raw Materials | B24: 4371.46 | C24: 4362.29 | D24: 4097.2 | E24: 5618.64 | F24: 4739.89 | G24: 4977.62 | H24: 5699.59 | J24: Other Current Liabilities | K24: 406.59 | L24: 455.04 | M24: 548.66 | N24: 450.3 | O24: 399.52 | P24: 407.08 | Q24: 435.65
A25: Opening Stock of Raw Materials | B25: 1285.05 | C25: 1245.28 | D25: 1349.14 | E25: 1395.51 | F25: 1268.82 | G25: 1205.94 | H25: 1281.48 | J25: Short-Term Provisions | K25: 480.14 | L25: 546.07 | M25: 625.13 | N25: 631.39 | O25: 646.74 | P25: 754.53 | Q25: 832.86
A26: Purchases of Raw Material | B26: 3072.48 | C26: 3103.03 | D26: 2056.32 | E26: 1886.11 | F26: 3512.68 | G26: 3441.97 | H26: 3740.56 | J26: Total Current Liabilities | K26: 2368.08 | L26: 2619.29 | M26: 2691.94 | N26: 2659.34 | O26: 2699.74 | P26: 2862.25 | Q26: 3183.42
A27: Purchase of Trading Goods | B27: 1259.21 | C27: 1363.12 | D27: 1847.85 | E27: 2850.85 | F27: 1993.39 | G27: 2360.41 | H27: 2056.75 | J27: Other Equity & Liabilities | K27: 0 | L27: 0 | M27: 0 | N27: 0 | O27: 0 | P27: 0 | Q27: 0
A28: Closing Stock of Raw Materials | B28: 1245.28 | C28: 1349.14 | D28: 1395.51 | E28: 1065.76 | F28: 1205.94 | G28: 1281.48 | H28: 1379.2 | J28: TOTAL EQUITY AND LIABILITIES | K28: 18418.81 | L28: 20405.66 | M28: 22963.74 | N28: 25449.05 | O28: 27596.47 | P28: 31053.23 | Q28: 35565.72
A29: Adjustment on amalgamation / trial runs | B29: 0 | C29: 0 | D29: 239.4 | E29: 551.93 | F29: -829.06 | G29: -749.22 | H29: 0 | J29: Non-Current Assets
A30: Power & Fuel Cost | B30: 264.93 | C30: 253.95 | D30: 234.58 | E30: 247.58 | F30: 257.07 | G30: 271.66 | H30: 290.24 | J30: Fixed Assets | K30: 4424.79 | L30: 4344.27 | M30: 4297.77 | N30: 4114.25 | O30: 4251.53 | P30: 4273.41 | Q30: 4403.16
A31: Power, Oil & Fuel | B31: 264.93 | C31: 253.95 | D31: 234.58 | E31: 247.58 | F31: 257.07 | G31: 271.66 | H31: 290.24 | J31: Tangible Assets | K31: 3992.13 | L31: 3686.18 | M31: 3569.27 | N31: 3554.91 | O31: 3449.67 | P31: 3278.31 | Q31: 3347.53
A32: Employee Cost | B32: 1839.84 | C32: 1911.08 | D32: 1703.58 | E32: 1729.16 | F32: 2380.68 | G32: 2688.51 | H32: 3054.87 | J32: Intangible Assets | K32: 135.33 | L32: 205.87 | M32: 269.51 | N32: 215.96 | O32: 199.45 | P32: 232.75 | Q32: 257.12
A33: Salaries,Wages & Bonus | B33: 1633.63 | C33: 1724 | D33: 1835.46 | E33: 1914.9 | F33: 2132.71 | G33: 2418.16 | H33: 2722.23 | J33: Capital Work-in-Progress | K33: 241.32 | L33: 255.73 | M33: 275.04 | N33: 186.26 | O33: 441.53 | P33: 580.9 | Q33: 523.11
A34: Contribution to funds | B34: 98 | C34: 96.77 | D34: 95.13 | E34: 90.65 | F34: 93.51 | G34: 101.46 | H34: 127.02 | J34: Intangible assets under development | K34: 56.01 | L34: 64 | M34: 80.07 | N34: 81.42 | O34: 62.72 | P34: 89.37 | Q34: 115.29
A35: Staff Welfare Expenses | B35: 86.2 | C35: 71.75 | D35: 93.51 | E35: 96.78 | F35: 130.99 | G35: 143.82 | H35: 178.47 | J35: Right-of-Use Assets | L35: 132.49 | M35: 103.88 | N35: 75.7 | O35: 98.16 | P35: 92.08 | Q35: 160.11
A36: Other Employee Cost | B36: 22.01 | C36: 18.56 | D36: -320.52 | E36: -373.17 | F36: 23.47 | G36: 25.07 | H36: 27.15 | J36: Non-Current Investments | K36: 3865.46 | L36: 6481.76 | M36: 7844.78 | N36: 8998.23 | O36: 9199.63 | P36: 9525.66 | Q36: 10614.55
A37: Other Manufacturing Expenses | B37: 861.96 | C37: 921.04 | D37: 906.09 | E37: 994.55 | F37: 988.99 | G37: 1243.47 | H37: 1374.94 | J37: Deferred Tax Assets (net) | K37: 0 | L37: 0 | M37: 0 | N37: 0 | O37: 0 | P37: 0 | Q37: 19.88
A38: Job Work / Contract / Processing Charges | B38: 158.93 | C38: 178.38 | D38: 189.43 | E38: 180.11 | F38: 207.56 | G38: 241.35 | H38: 269.03 | J38: Deferred Tax Assets | K38: 451.93 | L38: 240.65 | M38: 0 | N38: 234.44 | O38: 249.95 | P38: 211.07 | Q38: 0
A39: Stores Consumed | B39: 100.49 | C39: 120.33 | D39: 98.18 | E39: 107.94 | F39: 103.85 | G39: 110.49 | H39: 132.58 | J39: Deferred Tax Liability | K39: 494.77 | L39: 353.62 | M39: 104.91 | N39: 313.69 | O39: 286.08 | P39: 243.71 | Q39: 0
A40: Repairs | B40: 108.8 | C40: 120.62 | D40: 119.41 | E40: 145.81 | F40: 156.53 | G40: 159.94 | H40: 178.27 | J40: Long-Term Loans and Advances | K40: 609.23 | L40: 539.32 | M40: 615.26 | N40: 555.68 | O40: 748.77 | P40: 1904.67 | Q40: 1735.25
A41: Repairs - Plant & machinery | B41: 78.42 | C41: 93.46 | D41: 93.91 | E41: 115.29 | F41: 123.56 | G41: 127.59 | H41: 148.22 | J41: Other Non-Current Assets | K41: 40.68 | L41: 13.25 | M41: 13.75 | N41: 346.98 | O41: 25.41 | P41: 442.69 | Q41: 384.11
...

Sheet CF Assumptions
B1: CIPLA LIMITED – CASH FLOW STATEMENT (PROJECTED)
B2: INR in Crores | Actual FY2019–FY2025 from Raw Data | Forecast FY2026–FY2030 from Financial Statements & PPE Schedule
B4: Particulars | C4: 2019 Actual | D4: 2020 Actual | E4: 2021 Actual | F4: 2022 Actual | G4: 2023 Actual | H4: 2024 Actual | I4: 2025 Actual | J4: 2026 Forecast | K4: 2027 Forecast | L4: 2028 Forecast | M4: 2029 Forecast | N4: 2030 Forecast
B5: Cash at Beginning of Year | C5: ='Raw Data'!B107 -> 217.45 | D5: ='Raw Data'!C107 -> 64.47 | E5: ='Raw Data'!D107 -> 261.54 | F5: ='Raw Data'!E107 -> 294.72 | G5: ='Raw Data'!F107 -> 177.29 | H5: ='Raw Data'!G107 -> 29.48 | I5: ='Raw Data'!H107 -> 164.52 | J5: =I22 -> 82.74 | K5: =J22 -> -2372.6913 | L5: =K22 -> -4161.3044 | M5: =L22 -> -6187.9299 | N5: =M22 -> -8388.8392
B6: OPERATING ACTIVITIES
B7: Net Profit After Tax (PAT) | C7: ='Raw Data'!B77 -> 1888.41 | D7: ='Raw Data'!C77 -> 2318.17 | E7: ='Raw Data'!D77 -> 2468.28 | F7: ='Raw Data'!E77 -> 2957.93 | G7: ='Raw Data'!F77 -> 2513.47 | H7: ='Raw Data'!G77 -> 4077.25 | I7: ='Raw Data'!H77 -> 5157.65 | J7: ='Financial Statements'!J25 -> 1500.2186 | K7: ='Financial Statements'!K25 -> 1673.3212 | L7: ='Financial Statements'!L25 -> 1821.2089 | M7: ='Financial Statements'!M25 -> 2043.3786 | N7: ='Financial Statements'!N25 -> 2533.9679
B8: Add: Depreciation & Amortisation | C8: ='Raw Data'!B71 -> 569.72 | D8: ='Raw Data'!C71 -> 599.78 | E8: ='Raw Data'!D71 -> 468.62 | F8: ='Raw Data'!E71 -> 460.01 | G8: ='Raw Data'!F71 -> 595.91 | H8: ='Raw Data'!G71 -> 587.59 | I8: ='Raw Data'!H71 -> 573.89 | J8: ='Financial Statements'!J17 -> 704.5056 | K8: ='Financial Statements'!K17 -> 713.53092 | L8: ='Financial Statements'!L17 -> 736.83114 | M8: ='Financial Statements'!M17 -> 721.05845 | N8: ='Financial Statements'!N17 -> 761.29694
B9: Add: Finance Cost (Non-Cash Add-Back) | C9: ='Raw Data'!B67 -> 16.97 | D9: ='Raw Data'!C67 -> 36.05 | E9: ='Raw Data'!D67 -> 45.07 | F9: ='Raw Data'!E67 -> 26.93 | G9: ='Raw Data'!F67 -> 22.27 | H9: ='Raw Data'!G67 -> 20.25 | I9: ='Raw Data'!H67 -> 15.11 | J9: ='Financial Statements'!J18 -> 18 | K9: ='Financial Statements'!K18 -> 18 | L9: ='Financial Statements'!L18 -> 20 | M9: ='Financial Statements'!M18 -> 20 | N9: ='Financial Statements'!N18 -> 22
B10: (Inc)/Dec in Inventories | D10: ='Raw Data'!B45-'Raw Data'!C45 -> 16.34 | E10: ='Raw Data'!C45-'Raw Data'!D45 -> -19.86 | F10: ='Raw Data'!D45-'Raw Data'!E45 -> -26.04 | G10: ='Raw Data'!E45-'Raw Data'!F45 -> -8.61 | H10: ='Raw Data'!F45-'Raw Data'!G45 -> -3.02 | I10: ='Raw Data'!G45-'Raw Data'!H45 -> 3.76 | J10: ='Financial Statements'!I62-'Financial Statements'!J62 -> -1164.6432 | K10: ='Financial Statements'!J62-'Financial Statements'!K62 -> -382.32872 | L10: ='Financial Statements'!K62-'Financial Statements'!L62 -> -389.53874 | M10: ='Financial Statements'!L62-'Financial Statements'!M62 -> -288.23571 | N10: ='Financial Statements'!M62-'Financial Statements'!N62 -> -301.9276
B11: (Inc)/Dec in Trade Receivables | D11: ='Raw Data'!B46-'Raw Data'!C46 -> 16.34 | E11: ='Raw Data'!C46-'Raw Data'!D46 -> -19.86 | F11: ='Raw Data'!D46-'Raw Data'!E46 -> -26.04 | G11: ='Raw Data'!E46-'Raw Data'!F46 -> -8.61 | H11: ='Raw Data'!F46-'Raw Data'!G46 -> -3.02 | I11: ='Raw Data'!G46-'Raw Data'!H46 -> 3.76 | J11: ='Financial Statements'!I63-'Financial Statements'!J63 -> -797.76137 | K11: ='Financial Statements'!J63-'Financial Statements'!K63 -> -278.59786 | L11: ='Financial Statements'!K63-'Financial Statements'!L63 -> -192.62234 | M11: ='Financial Statements'!L63-'Financial Statements'!M63 -> -207.60539 | N11: ='Financial Statements'!M63-'Financial Statements'!N63 -> -396.98665
B12: Inc/(Dec) in Trade Payables | D12: ='Raw Data'!C23-'Raw Data'!B23 -> 0 | E12: ='Raw Data'!D23-'Raw Data'!C23 -> 0 | F12: ='Raw Data'!E23-'Raw Data'!D23 -> 0 | G12: ='Raw Data'!F23-'Raw Data'!E23 -> 0 | H12: ='Raw Data'!G23-'Raw Data'!F23 -> 0 | I12: ='Raw Data'!H23-'Raw Data'!G23 -> 0 | J12: ='Financial Statements'!J47-'Financial Statements'!I47 -> 508.32697 | K12: ='Financial Statements'!K47-'Financial Statements'!J47 -> 180.51576 | L12: ='Financial Statements'!L47-'Financial Statements'!K47 -> 166.2532 | M12: ='Financial Statements'!M47-'Financial Statements'!L47 -> 151.91195 | N12: ='Financial Statements'!N47-'Financial Statements'!M47 -> 197.93537
B13: Net Cash from Operating Activities (CFO) | C13: ='Raw Data'!B108 -> 1468.05 | D13: ='Raw Data'!C108 -> 2018.14 | E13: ='Raw Data'!D108 -> 3460.31 | F13: ='Raw Data'!E108 -> 2773.43 | G13: ='Raw Data'!F108 -> 3035.05 | H13: ='Raw Data'!G108 -> 3726.77 | I13: ='Raw Data'!H108 -> 3300.99 | J13: =J7+J8+J9+J10+J11+J12 -> 768.64659 | K13: =K7+K8+K9+K10+K11+K12 -> 1924.4413 | L13: =L7+L8+L9+L10+L11+L12 -> 2162.1322 | M13: =M7+M8+M9+M10+M11+M12 -> 2440.5079 | N13: =N7+N8+N9+N10+N11+N12 -> 2816.286
B14: INVESTING ACTIVITIES
B15: Purchase of Fixed Assets (Capex) – from Cash Flow Statement | C15: ='Raw Data'!B109 -> -312.05 | D15: ='Raw Data'!C109 -> -449.71 | E15: ='Raw Data'!D109 -> -516.97 | F15: ='Raw Data'!E109 -> -331.68 | G15: ='Raw Data'!F109 -> -684.15 | H15: ='Raw Data'!G109 -> -682.71 | I15: ='Raw Data'!H109 -> -728.68 | J15: =-'PPE Schedule'!J8 -> -760.91385 | K15: =-'PPE Schedule'!K8 -> -859.15732 | L15: =-'PPE Schedule'!L8 -> -938.69285 | M15: =-'PPE Schedule'!M8 -> -989.31504 | N15: =-'PPE Schedule'!N8 -> -1119.8186
B16: Other Investing Activities (Investments & Others) | C16: ='Raw Data'!B110-'Raw Data'!B109 -> -835.66 | D16: ='Raw Data'!C110-'Raw Data'!C109 -> -677.47 | E16: ='Raw Data'!D110-'Raw Data'!D109 -> -2844.36 | F16: ='Raw Data'!E110-'Raw Data'!E109 -> -2132.46 | G16: ='Raw Data'!F110-'Raw Data'!F109 -> -2073.94 | H16: ='Raw Data'!G110-'Raw Data'!G109 -> -2200.19 | I16: ='Raw Data'!H110-'Raw Data'!H109 -> -1580.16 | J16: =-('Financial Statements'!J57-'Financial Statements'!I57) -> -849.164 | K16: =-('Financial Statements'!K57-'Financial Statements'!J57) -> -917.09712 | L16: =-('Financial Statements'!L57-'Financial Statements'!K57) -> -990.46489 | M16: =-('Financial Statements'!M57-'Financial Statements'!L57) -> -1069.7021 | N16: =-('Financial Statements'!N57-'Financial Statements'!M57) -> -1155.2782
B17: Net Cash Used in Investing Activities (CFI) | C17: ='Raw Data'!B110 -> -1147.71 | D17: ='Raw Data'!C110 -> -1127.18 | E17: ='Raw Data'!D110 -> -3361.33 | F17: ='Raw Data'!E110 -> -2464.14 | G17: ='Raw Data'!F110 -> -2758.09 | H17: ='Raw Data'!G110 -> -2882.9 | I17: ='Raw Data'!H110 -> -2308.84 | J17: =J15+J16 -> -1610.0778 | K17: =K15+K16 -> -1776.2544 | L17: =L15+L16 -> -1929.1577 | M17: =M15+M16 -> -2059.0171 | N17: =N15+N16 -> -2275.0969
B18: FINANCING ACTIVITIES
B19: Dividends Paid | C19: ='Raw Data'!B111 -> -473.32 | D19: ='Raw Data'!C111 -> -693.89 | E19: ='Raw Data'!D111 -> -65.8 | F19: ='Raw Data'!E111 -> -426.72 | G19: ='Raw Data'!F111 -> -424.77 | H19: ='Raw Data'!G111 -> -708.83 | I19: ='Raw Data'!H111 -> -1073.93 | J19: =-('Financial Statements'!J29*'IS ,BS Assumptions'!I54) -> -1614 | K19: =-('Financial Statements'!K29*'IS ,BS Assumptions'!J54) -> -1936.8 | L19: =-('Financial Statements'!L29*'IS ,BS Assumptions'!K54) -> -2259.6 | M19: =-('Financial Statements'!M29*'IS ,BS Assumptions'!L54) -> -2582.4 | N19: =-('Financial Statements'!N29*'IS ,BS Assumptions'!M54) -> -2905.2
B20: Net Cash Used in Financing Activities (CFF) | C20: ='Raw Data'!B111 -> -473.32 | D20: ='Raw Data'!C111 -> -693.89 | E20: ='Raw Data'!D111 -> -65.8 | F20: ='Raw Data'!E111 -> -426.72 | G20: ='Raw Data'!F111 -> -424.77 | H20: ='Raw Data'!G111 -> -708.83 | I20: ='Raw Data'!H111 -> -1073.93 | J20: =J19 -> -1614 | K20: =K19 -> -1936.8 | L20: =L19 -> -2259.6 | M20: =M19 -> -2582.4 | N20: =N19 -> -2905.2
B21: Net Inc/(Dec) in Cash & Cash Equivalents | C21: ='Raw Data'!B112 -> -152.98 | D21: ='Raw Data'!C112 -> 197.07 | E21: ='Raw Data'!D112 -> 33.18 | F21: ='Raw Data'!E112 -> -117.43 | G21: ='Raw Data'!F112 -> -147.81 | H21: ='Raw Data'!G112 -> 135.04 | I21: ='Raw Data'!H112 -> -81.78 | J21: =J13+J17+J20 -> -2455.4313 | K21: =K13+K17+K20 -> -1788.6131 | L21: =L13+L17+L20 -> -2026.6255 | M21: =M13+M17+M20 -> -2200.9093 | N21: =N13+N17+N20 -> -2364.0109
B22: Cash at End of Year | C22: ='Raw Data'!B113 -> 64.47 | D22: ='Raw Data'!C113 -> 261.54 | E22: ='Raw Data'!D113 -> 294.72 | F22: ='Raw Data'!E113 -> 177.29 | G22: ='Raw Data'!F113 -> 29.48 | H22: ='Raw Data'!G113 -> 164.52 | I22: ='Raw Data'!H113 -> 82.74 | J22: =J5+J21 -> -2372.6913 | K22: =K5+K21 -> -4161.3044 | L22: =L5+L21 -> -6187.9299 | M22: =M5+M21 -> -8388.8392 | N22: =N5+N21 -> -10752.85

Sheet IS ,BS Assumptions
A1: CIPLA LIMITED – ASSUMPTIONS
J3: Scenarios: | L3: Y-o-Y Growth
A4: Select Case | B4: Case 2 | J4: Case 1 | K4: Optimistic Case | L4: 0.1
J5: Case 2 | K5: Base Case | L5: 0.08
J6: Case 3 | K6: Worst Case | L6: 0.06
A8: Particulars | B8: 2019 Actual | C8: 2020 Actual | D8: 2021 Actual | E8: 2022 Actual | F8: 2023 Actual | G8: 2024 Actual | H8: 2025 Actual | I8: 2026 Forecast | J8: 2027 Forecast | K8: 2028 Forecast | L8: 2029 Forecast | M8: 2030 Forecast
A9: P&L ASSUMPTIONS
A10: Revenue from Operations (INR Cr.) | B10: ='Raw Data'!B8 -> 12374.01 | C10: ='Raw Data'!C8 -> 12659.15 | D10: ='Raw Data'!D8 -> 11302.71 | E10: ='Raw Data'!E8 -> 13091.79 | F10: ='Raw Data'!F8 -> 14345.34 | G10: ='Raw Data'!G8 -> 16574.34 | H10: ='Raw Data'!H8 -> 19044.85 | I10: =H10*(1+I11) -> 20568.438 | J10: =I10*(1+J11) -> 22213.913 | K10: =J10*(1+K11) -> 23991.026 | L10: =K10*(1+L11) -> 25910.308 | M10: =L10*(1+M11) -> 27983.133
A11: Revenue Growth YoY % | C11: =(C10-B10)/B10 -> 0.02304346 | D11: =(D10-C10)/C10 -> -0.10715095 | E11: =(E10-D10)/D10 -> 0.1582877 | F11: =(F10-E10)/E10 -> 0.095750848 | G11: =(G10-F10)/F10 -> 0.15538147 | H11: =(H10-G10)/G10 -> 0.14905631 | I11: =VLOOKUP($B$4,$J$4:$L$6,3,FALSE) -> 0.08 | J11: =VLOOKUP($B$4,$J$4:$L$6,3,FALSE) -> 0.08 | K11: =VLOOKUP($B$4,$J$4:$L$6,3,FALSE) -> 0.08 | L11: =VLOOKUP($B$4,$J$4:$L$6,3,FALSE) -> 0.08 | M11: =VLOOKUP($B$4,$J$4:$L$6,3,FALSE) -> 0.08
A13: Other Income (INR Cr.) | B13: ='Raw Data'!B9 -> 577.52 | C13: ='Raw Data'!C9 -> 892.85 | D13: ='Raw Data'!D9 -> 653.91 | E13: ='Raw Data'!E9 -> 935.24 | F13: ='Raw Data'!F9 -> 826.2 | G13: ='Raw Data'!G9 -> 1433.72 | H13: ='Raw Data'!H9 -> 1279.38 | I13: =I15*I10 -> 1345.0779 | J13: =J15*J10 -> 1512.1007 | K13: =K15*K10 -> 1624.6375 | L13: =L15*L10 -> 1791.1208 | M13: =M15*M10 -> 1925.1785
A14: Other Income % of Revenue | B14: =B13/B10 -> 0.046672017 | C14: =C13/C10 -> 0.070530012 | D14: =D13/D10 -> 0.057854267 | E14: =E13/E10 -> 0.071437137 | F14: =F13/F10 -> 0.057593616 | G14: =G13/G10 -> 0.086502389 | H14: =H13/H10 -> 0.067177216
A15: Assumed Other Income % | I15: =AVERAGE(B14:H14) -> 0.065395236 | J15: =AVERAGE(C14:H14,I15:I15) -> 0.068069982 | K15: =AVERAGE(D14:H14,I15:J15) -> 0.067718549 | L15: =AVERAGE(E14:H14,I15:K15) -> 0.069127732 | M15: =AVERAGE(F14:H14,I15:L15) -> 0.068797817
A17: Raw Materials Consumed (INR Cr.) | B17: ='Raw Data'!B24 -> 4371.46 | C17: ='Raw Data'!C24 -> 4362.29 | D17: ='Raw Data'!D24 -> 4097.2 | E17: ='Raw Data'!E24 -> 5618.64 | F17: ='Raw Data'!F24 -> 4739.89 | G17: ='Raw Data'!G24 -> 4977.62 | H17: ='Raw Data'!H24 -> 5699.59
A18: Purchase of Trading Goods (INR Cr.) | B18: ='Raw Data'!B27 -> 1259.21 | C18: ='Raw Data'!C27 -> 1363.12 | D18: ='Raw Data'!D27 -> 1847.85 | E18: ='Raw Data'!E27 -> 2850.85 | F18: ='Raw Data'!F27 -> 1993.39 | G18: ='Raw Data'!G27 -> 2360.41 | H18: ='Raw Data'!H27 -> 2056.75
A19: Total Material Cost (INR Cr.) | B19: =B17+B18 -> 5630.67 | C19: =C17+C18 -> 5725.41 | D19: =D17+D18 -> 5945.05 | E19: =E17+E18 -> 8469.49 | F19: =F17+F18 -> 6733.28 | G19: =G17+G18 -> 7338.03 | H19: =H17+H18 -> 7756.34
A20: Material Cost % of Revenue | B20: =B19/B10 -> 0.45504004 | C20: =C19/C10 -> 0.45227444 | D20: =D19/D10 -> 0.52598448 | E20: =E19/E10 -> 0.6469314 | F20: =F19/F10 -> 0.46937054 | G20: =G19/G10 -> 0.44273437 | H20: =H19/H10 -> 0.40726706
A21: Assumed Material Cost % (= Average of Actuals FY2019–FY2025) | I21: =AVERAGE(B20:H20) -> 0.48565747 | J21: =AVERAGE(C20:H20,I21:I21) -> 0.49003139 | K21: =AVERAGE(D20:H20,I21:J21) -> 0.49542524 | L21: =AVERAGE(E20:H20,I21:K21) -> 0.49105964 | M21: =AVERAGE(F20:H20,I21:L21) -> 0.46879225
A22: Material Cost – Forecast (INR Cr.) | B22: =B19 -> 5630.67 | C22: =C19 -> 5725.41 | D22: =D19 -> 5945.05 | E22: =E19 -> 8469.49 | F22: =F19 -> 6733.28 | G22: =G19 -> 7338.03 | H22: =H19 -> 7756.34 | I22: =I10*I21 -> 9989.2157 | J22: =J10*J21 -> 10885.515 | K22: =K10*K21 -> 11885.76 | L22: =L10*L21 -> 12723.507 | M22: =M10*M21 -> 13118.276
A25: Employee Cost (INR Cr.) | B25: ='Raw Data'!B32 -> 1839.84 | C25: ='Raw Data'!C32 -> 1911.08 | D25: ='Raw Data'!D32 -> 1703.58 | E25: ='Raw Data'!E32 -> 1729.16 | F25: ='Raw Data'!F32 -> 2380.68 | G25: ='Raw Data'!G32 -> 2688.51 | H25: ='Raw Data'!H32 -> 3054.87
A26: Employee Cost % of Revenue | B26: =B25/B10 -> 0.14868583 | C26: =C25/C10 -> 0.15096432 | D26: =D25/D10 -> 0.15072315 | E26: =E25/E10 -> 0.13207972 | F26: =F25/F10 -> 0.16595494 | G26: =G25/G10 -> 0.16220917 | H26: =H25/H10 -> 0.16040399
A27: Assumed Employee Cost % (= Average of Actuals FY2019–FY2025) | I27: =AVERAGE(B26:H26) -> 0.15300302 | J27: =AVERAGE(C26:H26,I27:I27) -> 0.15361976 | K27: =AVERAGE(D26:H26,I27:J27) -> 0.15399911 | L27: =AVERAGE(E26:H26,I27:K27) -> 0.1544671 | M27: =AVERAGE(F26:H26,I27:L27) -> 0.1576653
A29: Employee Cost – Forecast (INR Cr.) | B29: =B25 -> 1839.84 | C29: =C25 -> 1911.08 | D29: =D25 -> 1703.58 | E29: =E25 -> 1729.16 | F29: =F25 -> 2380.68 | G29: =G25 -> 2688.51 | H29: =H25 -> 3054.87 | I29: =I10*I27 -> 3147.0331 | J29: =J10*J27 -> 3412.496 | K29: =K10*K27 -> 3694.5966 | L29: =L10*L27 -> 4002.2902 | M29: =M10*M27 -> 4411.969
A31: Other Operating Expenses (INR Cr.) | B31: ='Raw Data'!B30+'Raw Data'!B37+'Raw Data'!B44+'Raw Data'!B50+'Raw Data'!B57 -> 3949.95 | C31: ='Raw Data'!C30+'Raw Data'!C37+'Raw Data'!C44+'Raw Data'!C50+'Raw Data'!C57 -> 4278.7 | D31: ='Raw Data'!D30+'Raw Data'!D37+'Raw Data'!D44+'Raw Data'!D50+'Raw Data'!D57 -> 2899.99 | E31: ='Raw Data'!E30+'Raw Data'!E37+'Raw Data'!E44+'Raw Data'!E50+'Raw Data'!E57 -> 3448.82 | F31: ='Raw Data'!F30+'Raw Data'!F37+'Raw Data'!F44+'Raw Data'!F50+'Raw Data'!F57 -> 4457.55 | G31: ='Raw Data'!G30+'Raw Data'!G37+'Raw Data'!G44+'Raw Data'!G50+'Raw Data'!G57 -> 4995.56 | H31: ='Raw Data'!H30+'Raw Data'!H37+'Raw Data'!H44+'Raw Data'!H50+'Raw Data'!H57 -> 5542.32
A32: Other Opex % of Revenue | B32: =B31/B10 -> 0.31921342 | C32: =C31/C10 -> 0.33799268 | D32: =D31/D10 -> 0.25657475 | E32: =E31/E10 -> 0.2634338 | F32: =F31/F10 -> 0.31073157 | G32: =G31/G10 -> 0.30140325 | H32: =H31/H10 -> 0.29101411
A33: Assumed Other Opex % (= Average of Actuals FY2019–FY2025) | I33: =AVERAGE(B32:H32) -> 0.2971948 | J33: =AVERAGE(C32:H32,I33:I33) -> 0.29404928 | K33: =AVERAGE(D32:H32,I33:J33) -> 0.28777165 | L33: =AVERAGE(E32:H32,I33:K33) -> 0.29222835 | M33: =AVERAGE(F32:H32,I33:L33) -> 0.29634186
A34: Other Opex – Forecast (INR Cr.) | B34: =B31 -> 3949.95 | C34: =C31 -> 4278.7 | D34: =D31 -> 2899.99 | E34: =E31 -> 3448.82 | F34: =F31 -> 4457.55 | G34: =G31 -> 4995.56 | H34: =H31 -> 5542.32 | I34: =I10*I33 -> 6112.8327 | J34: =J10*J33 -> 6531.9851 | K34: =K10*K33 -> 6903.9372 | L34: =L10*L33 -> 7571.7266 | M34: =M10*M33 -> 8292.5736
A36: Finance Cost / Interest (INR Cr.) | B36: ='Raw Data'!B67 -> 16.97 | C36: ='Raw Data'!C67 -> 36.05 | D36: ='Raw Data'!D67 -> 45.07 | E36: ='Raw Data'!E67 -> 26.93 | F36: ='Raw Data'!F67 -> 22.27 | G36: ='Raw Data'!G67 -> 20.25 | H36: ='Raw Data'!H67 -> 15.11 | I36: 18 | J36: 18 | K36: 20 | L36: 20 | M36: 22
A37: Depreciation & Amortisation – from PPE Schedule | B37: ='Raw Data'!B71 -> 569.72 | C37: ='Raw Data'!C71 -> 599.78 | D37: ='Raw Data'!D71 -> 468.62 | E37: ='Raw Data'!E71 -> 460.01 | F37: ='Raw Data'!F71 -> 595.91 | G37: ='Raw Data'!G71 -> 587.59 | H37: ='Raw Data'!H71 -> 573.89 | I37: ='PPE Schedule'!J12 -> 704.5056 | J37: ='PPE Schedule'!K12 -> 713.53092 | K37: ='PPE Schedule'!L12 -> 736.83114 | L37: ='PPE Schedule'!M12 -> 721.05845 | M37: ='PPE Schedule'!N12 -> 761.29694
A39: TAX ASSUMPTIONS
A40: Historical Effective Tax Rate | B40: ='Raw Data'!B73/'Raw Data'!B72 -> 0.23123518 | C40: ='Raw Data'!C73/'Raw Data'!C72 -> 0.18417777 | D40: ='Raw Data'!D73/'Raw Data'!D72 -> 0.23577221 | E40: ='Raw Data'!E73/'Raw Data'!E72 -> 0.23258021 | F40: ='Raw Data'!F73/'Raw Data'!F72 -> 0.26714884 | G40: ='Raw Data'!G73/'Raw Data'!G72 -> 0.23101376 | H40: ='Raw Data'!H73/'Raw Data'!H72 -> 0.21028874
A41: Assumed Tax Rate – 23.62% from Parameters (= Average of Actuals FY2019–FY2025) | I41: =AVERAGE(B40:H40) -> 0.22745953 | J41: =AVERAGE(C40:H40,I41:I41) -> 0.22692015 | K41: =AVERAGE(D40:H40,I41:J41) -> 0.2330262 | L41: =AVERAGE(E40:H40,I41:K41) -> 0.23263392 | M41: =AVERAGE(F40:H40,I41:L41) -> 0.23264159
A44: Particulars | B44: 2019 Actual | C44: 2020 Actual | D44: 2021 Actual | E44: 2022 Actual | F44: 2023 Actual | G44: 2024 Actual | H44: 2025 Actual | I44: 2026 Forecast | J44: 2027 Forecast | K44: 2028 Forecast | L44: 2029 Forecast | M44: 2030 Forecast
A45: BALANCE SHEET ASSUMPTIONS
A46: Inventory Days (Historical) | B46: ='Raw Data'!K45/'Raw Data'!B8*365 -> 84.610377 | C46: ='Raw Data'!L45/'Raw Data'!C8*365 -> 87.114569 | D46: ='Raw Data'!M45/'Raw Data'!D8*365 -> 99.650495 | E46: ='Raw Data'!N45/'Raw Data'!E8*365 -> 97.184621 | F46: ='Raw Data'!O45/'Raw Data'!F8*365 -> 83.388501 | G46: ='Raw Data'!P45/'Raw Data'!G8*365 -> 71.665731 | H46: ='Raw Data'!Q45/'Raw Data'!H8*365 -> 69.131487 | I46: 84 | J46: 82 | K46: 80 | L46: 78 | M46: 76
A47: Assumed Inventory Days (= Average of Actuals FY2019–FY2025) | I47: =AVERAGE(B46:H46) -> 84.677969 | J47: =AVERAGE(C46:H46,I47:I47) -> 84.687625 | K47: =AVERAGE(D46:H46,I47:J47) -> 84.340919 | L47: =AVERAGE(E46:H46,I47:K47) -> 82.153836 | M47: =AVERAGE(F46:H46,I47:L47) -> 80.006581
A48: Receivable Days (Historical) | B48: ='Raw Data'!K46/'Raw Data'!B8*365 -> 93.469009 | C48: ='Raw Data'!L46/'Raw Data'!C8*365 -> 102.65291 | D48: ='Raw Data'!M46/'Raw Data'!D8*365 -> 98.021629 | E48: ='Raw Data'!N46/'Raw Data'!E8*365 -> 77.910293 | F48: ='Raw Data'!O46/'Raw Data'!F8*365 -> 73.49417 | G48: ='Raw Data'!P46/'Raw Data'!G8*365 -> 59.05748 | H48: ='Raw Data'!Q46/'Raw Data'!H8*365 -> 73.977813 | I48: 72 | J48: 70 | K48: 68 | L48: 66 | M48: 65
A49: Assumed Receivable Days (= Average of Actuals FY2019–FY2025) | I49: =AVERAGE(B48:H48) -> 82.654757 | J49: =AVERAGE(C48:H48,I49:I49) -> 81.109864 | K49: =AVERAGE(D48:H48,I49:J49) -> 78.032287 | L49: =AVERAGE(E48:H48,I49:K49) -> 75.176666 | M49: =AVERAGE(F48:H48,I49:L49) -> 74.786148
A50: Payable Days (Historical) | B50: ='Raw Data'!K23/'Raw Data'!B8*365 -> 43.695839 | C50: ='Raw Data'!L23/'Raw Data'!C8*365 -> 46.482094 | D50: ='Raw Data'!M23/'Raw Data'!D8*365 -> 48.294068 | E50: ='Raw Data'!N23/'Raw Data'!E8*365 -> 43.76418 | F50: ='Raw Data'!O23/'Raw Data'!F8*365 -> 41.700357 | G50: ='Raw Data'!P23/'Raw Data'!G8*365 -> 37.09913 | H50: ='Raw Data'!Q23/'Raw Data'!H8*365 -> 36.101841 | I50: 34 | J50: 34 | K50: 34 | L50: 35 | M50: 35
A51: Assumed Payable Days (= Average of Actuals FY2019–FY2025) | I51: =AVERAGE(B50:H50) -> 42.448216 | J51: =AVERAGE(C50:H50,I51:I51) -> 42.269984 | K51: =AVERAGE(D50:H50,I51:J51) -> 41.668254 | L51: =AVERAGE(E50:H50,I51:K51) -> 40.721709 | M51: =AVERAGE(F50:H50,I51:L51) -> 40.28707
A52: Capex % of Revenue (Actuals from CF Statement | Forecast = Average of Actuals) | B52: =-'Raw Data'!B109/'Raw Data'!B8 -> 0.025218179 | C52: =-'Raw Data'!C109/'Raw Data'!C8 -> 0.035524502 | D52: =-'Raw Data'!D109/'Raw Data'!D8 -> 0.045738588 | E52: =-'Raw Data'!E109/'Raw Data'!E8 -> 0.025334962 | F52: =-'Raw Data'!F109/'Raw Data'!F8 -> 0.047691445 | G52: =-'Raw Data'!G109/'Raw Data'!G8 -> 0.04119078 | H52: =-'Raw Data'!H109/'Raw Data'!H8 -> 0.038261262 | I52: =AVERAGE(B52:H52) -> 0.036994246 | J52: =AVERAGE(C52:I52) -> 0.038676541 | K52: =AVERAGE(D52:J52) -> 0.039126832 | L52: =AVERAGE(E52:K52) -> 0.038182296 | M52: =AVERAGE(F52:L52) -> 0.040017629
...

Sheet Financial Statements
B1: CIPLA LIMITED – PROJECTED FINANCIAL STATEMENTS
B5: Particulars | C5: 2019 Actual | D5: 2020 Actual | E5: 2021 Actual | F5: 2022 Actual | G5: 2023 Actual | H5: 2024 Actual | I5: 2025 Actual | J5: 2026 Forecast | K5: 2027 Forecast | L5: 2028 Forecast | M5: 2029 Forecast | N5: 2030 Forecast
B6: INCOME STATEMENT
B7: Revenue from Operations | C7: ='IS ,BS Assumptions'!B10 -> 12374.01 | D7: ='IS ,BS Assumptions'!C10 -> 12659.15 | E7: ='IS ,BS Assumptions'!D10 -> 11302.71 | F7: ='IS ,BS Assumptions'!E10 -> 13091.79 | G7: ='IS ,BS Assumptions'!F10 -> 14345.34 | H7: ='IS ,BS Assumptions'!G10 -> 16574.34 | I7: ='IS ,BS Assumptions'!H10 -> 19044.85 | J7: ='IS ,BS Assumptions'!I10 -> 20568.438 | ... N7: ='IS ,BS Assumptions'!M10 -> 27983.133
B8: Other Income | C8: ='IS ,BS Assumptions'!B13 -> 577.52 | D8: ='IS ,BS Assumptions'!C13 -> 892.85 | E8: ='IS ,BS Assumptions'!D13 -> 653.91 | F8: ='IS ,BS Assumptions'!E13 -> 935.24 | G8: ='IS ,BS Assumptions'!F13 -> 826.2 | H8: ='IS ,BS Assumptions'!G13 -> 1433.72 | I8: ='IS ,BS Assumptions'!H13 -> 1279.38 | J8: ='IS ,BS Assumptions'!I13 -> 1345.0779 | ... N8: ='IS ,BS Assumptions'!M13 -> 1925.1785
B9: Raw Materials & Trading Goods | C9: ='IS ,BS Assumptions'!B22 -> 5630.67 | D9: ='IS ,BS Assumptions'!C22 -> 5725.41 | E9: ='IS ,BS Assumptions'!D22 -> 5945.05 | F9: ='IS ,BS Assumptions'!E22 -> 8469.49 | G9: ='IS ,BS Assumptions'!F22 -> 6733.28 | H9: ='IS ,BS Assumptions'!G22 -> 7338.03 | I9: ='IS ,BS Assumptions'!H22 -> 7756.34 | J9: ='IS ,BS Assumptions'!I22 -> 9989.2157 | ... N9: ='IS ,BS Assumptions'!M22 -> 13118.276
B10: Employee Benefit Expenses | C10: ='IS ,BS Assumptions'!B29 -> 1839.84 | D10: ='IS ,BS Assumptions'!C29 -> 1911.08 | E10: ='IS ,BS Assumptions'!D29 -> 1703.58 | F10: ='IS ,BS Assumptions'!E29 -> 1729.16 | G10: ='IS ,BS Assumptions'!F29 -> 2380.68 | H10: ='IS ,BS Assumptions'!G29 -> 2688.51 | I10: ='IS ,BS Assumptions'!H29 -> 3054.87 | J10: ='IS ,BS Assumptions'!I29 -> 3147.0331 | ... N10: ='IS ,BS Assumptions'!M29 -> 4411.969
B11: Other Operating Expenses | C11: ='IS ,BS Assumptions'!B34 -> 3949.95 | D11: ='IS ,BS Assumptions'!C34 -> 4278.7 | E11: ='IS ,BS Assumptions'!D34 -> 2899.99 | F11: ='IS ,BS Assumptions'!E34 -> 3448.82 | G11: ='IS ,BS Assumptions'!F34 -> 4457.55 | H11: ='IS ,BS Assumptions'!G34 -> 4995.56 | I11: ='IS ,BS Assumptions'!H34 -> 5542.32 | J11: ='IS ,BS Assumptions'!I34 -> 6112.8327 | ... N11: ='IS ,BS Assumptions'!M34 -> 8292.5736
B12: Total Operating Expenditure | C12: =C9+C10+C11 -> 11420.46 | D12: =D9+D10+D11 -> 11915.19 | E12: =E9+E10+E11 -> 10548.62 | F12: =F9+F10+F11 -> 13647.47 | G12: =G9+G10+G11 -> 13571.51 | H12: =H9+H10+H11 -> 15022.1 | I12: =I9+I10+I11 -> 16353.53 | J12: =J9+J10+J11 -> 19249.082 | ... N12: =N9+N10+N11 -> 25822.818
B14: EBITDA | C14: =C7+C8-C12 -> 1531.07 | D14: =D7+D8-D12 -> 1636.81 | E14: =E7+E8-E12 -> 1408 | F14: =F7+F8-F12 -> 379.56 | G14: =G7+G8-G12 -> 1600.03 | H14: =H7+H8-H12 -> 2985.96 | I14: =I7+I8-I12 -> 3970.7 | J14: =J7+J8-J12 -> 2664.4344 | ... N14: =N7+N8-N12 -> 4085.493
B15: EBITDA Margin (%) | C15: =C14/C7 -> 0.12373273 | D15: =D14/D7 -> 0.12929857 | E15: =E14/E7 -> 0.12457189 | F15: =F14/F7 -> 0.028992216 | G15: =G14/G7 -> 0.11153657 | H15: =H14/H7 -> 0.18015559 | I15: =I14/I7 -> 0.20849206 | J15: =J14/J7 -> 0.12953995 | ... N15: =N14/N7 -> 0.14599841
B17: Depreciation & Amortisation | C17: ='IS ,BS Assumptions'!B37 -> 569.72 | D17: ='IS ,BS Assumptions'!C37 -> 599.78 | E17: ='IS ,BS Assumptions'!D37 -> 468.62 | F17: ='IS ,BS Assumptions'!E37 -> 460.01 | G17: ='IS ,BS Assumptions'!F37 -> 595.91 | H17: ='IS ,BS Assumptions'!G37 -> 587.59 | I17: ='IS ,BS Assumptions'!H37 -> 573.89 | J17: ='IS ,BS Assumptions'!I37 -> 704.5056 | ... N17: ='IS ,BS Assumptions'!M37 -> 761.29694
B18: Finance Costs / Interest | C18: ='IS ,BS Assumptions'!B36 -> 16.97 | D18: ='IS ,BS Assumptions'!C36 -> 36.05 | E18: ='IS ,BS Assumptions'!D36 -> 45.07 | F18: ='IS ,BS Assumptions'!E36 -> 26.93 | G18: ='IS ,BS Assumptions'!F36 -> 22.27 | H18: ='IS ,BS Assumptions'!G36 -> 20.25 | I18: ='IS ,BS Assumptions'!H36 -> 15.11 | J18: ='IS ,BS Assumptions'!I36 -> 18 | ... N18: ='IS ,BS Assumptions'!M36 -> 22
B20: EBIT | C20: =C14-C17 -> 961.35 | D20: =D14-D17 -> 1037.03 | E20: =E14-E17 -> 939.38 | F20: =F14-F17 -> -80.45 | G20: =G14-G17 -> 1004.12 | H20: =H14-H17 -> 2398.37 | I20: =I14-I17 -> 3396.81 | J20: =J14-J17 -> 1959.9288 | ... N20: =N14-N17 -> 3324.1961
B21: EBIT Margin (%) | C21: =C20/C7 -> 0.077691064 | D21: =D20/D7 -> 0.081919402 | E21: =E20/E7 -> 0.083111042 | F21: =F20/F7 -> -0.0061450726 | G21: =G20/G7 -> 0.06999625 | H21: =H20/H7 -> 0.1447038 | I21: =I20/I7 -> 0.17835845 | J21: =J20/J7 -> 0.095288167 | ... N21: =N20/N7 -> 0.11879285
B23: Profit Before Tax (PBT) | C23: ='Raw Data'!B72 -> 2492.83 | D23: ='Raw Data'!C72 -> 2964.31 | E23: ='Raw Data'!D72 -> 3207.63 | F23: ='Raw Data'!E72 -> 3814.77 | G23: ='Raw Data'!F72 -> 3375.01 | H23: ='Raw Data'!G72 -> 5310.03 | I23: ='Raw Data'!H72 -> 6468.82 | J23: =J20-J18 -> 1941.9288 | K23: =K20-K18 -> 2164.4869 | L23: =L20-L18 -> 2374.5387 | M23: =M20-M18 -> 2662.8471 | N23: =N20-N18 -> 3302.1961
B24: Tax Expense | C24: ='Raw Data'!B73 -> 576.43 | D24: ='Raw Data'!C73 -> 545.96 | E24: ='Raw Data'!D73 -> 756.27 | F24: ='Raw Data'!E73 -> 887.24 | G24: ='Raw Data'!F73 -> 901.63 | H24: ='Raw Data'!G73 -> 1226.69 | I24: ='Raw Data'!H73 -> 1360.32 | J24: =J23*'IS ,BS Assumptions'!I41 -> 441.7102 | K24: =K23*'IS ,BS Assumptions'!J41 -> 491.16569 | L24: =L23*'IS ,BS Assumptions'!K41 -> 553.32973 | M24: =M23*'IS ,BS Assumptions'!L41 -> 619.46856 | N24: =N23*'IS ,BS Assumptions'!M41 -> 768.22815
B25: Net Profit / PAT | C25: ='Raw Data'!B77 -> 1888.41 | D25: ='Raw Data'!C77 -> 2318.17 | E25: ='Raw Data'!D77 -> 2468.28 | F25: ='Raw Data'!E77 -> 2957.93 | G25: ='Raw Data'!F77 -> 2513.47 | H25: ='Raw Data'!G77 -> 4077.25 | I25: ='Raw Data'!H77 -> 5157.65 | J25: =J23-J24 -> 1500.2186 | K25: =K23-K24 -> 1673.3212 | L25: =L23-L24 -> 1821.2089 | M25: =M23-M24 -> 2043.3786 | N25: =N23-N24 -> 2533.9679
B26: PAT Margin (%) | C26: =C25/C7 -> 0.152611 | D26: =D25/D7 -> 0.18312209 | E26: =E25/E7 -> 0.21837949 | F26: =F25/F7 -> 0.22593778 | G26: =G25/G7 -> 0.1752116 | H26: =H25/H7 -> 0.24599773 | I26: =I25/I7 -> 0.27081599 | J26: =J25/J7 -> 0.072937894 | ... N26: =N25/N7 -> 0.090553404
B28: Earnings Per Share (INR) | C28: ='Raw Data'!B97 -> 23.44 | D28: ='Raw Data'!C97 -> 28.75 | E28: ='Raw Data'!D97 -> 30.61 | F28: ='Raw Data'!E97 -> 36.66 | G28: ='Raw Data'!F97 -> 31.14 | H28: ='Raw Data'!G97 -> 50.5 | I28: ='Raw Data'!H97 -> 63.86 | J28: =J25/'IS ,BS Assumptions'!I54 -> 18.590069 | K28: =K25/'IS ,BS Assumptions'!J54 -> 20.735083 | L28: =L25/'IS ,BS Assumptions'!K54 -> 22.567645 | M28: =M25/'IS ,BS Assumptions'!L54 -> 25.320676 | N28: =N25/'IS ,BS Assumptions'!M54 -> 31.39985
B29: Dividend Per Share (INR) | C29: ='Raw Data'!B96 -> 3 | D29: ='Raw Data'!C96 -> 4 | E29: ='Raw Data'!D96 -> 5 | F29: ='Raw Data'!E96 -> 5 | G29: ='Raw Data'!F96 -> 8.5 | H29: ='Raw Data'!G96 -> 13 | I29: ='Raw Data'!H96 -> 16 | J29: ='IS ,BS Assumptions'!I53 -> 20 | K29: ='IS ,BS Assumptions'!J53 -> 24 | L29: ='IS ,BS Assumptions'!K53 -> 28 | M29: ='IS ,BS Assumptions'!L53 -> 32 | N29: ='IS ,BS Assumptions'!M53 -> 36
B34: Particulars | C34: 2019 Actual | D34: 2020 Actual | E34: 2021 Actual | F34: 2022 Actual | G34: 2023 Actual | H34: 2024 Actual | I34: 2025 Actual | J34: 2026 Forecast | K34: 2027 Forecast | L34: 2028 Forecast | M34: 2029 Forecast | N34: 2030 Forecast
B35: BALANCE SHEET – EQUITY & LIABILITIES
B36: Share Capital | C36: ='Raw Data'!K7 -> 161.14 | D36: ='Raw Data'!L7 -> 161.25 | E36: ='Raw Data'!M7 -> 161.29 | F36: ='Raw Data'!N7 -> 161.36 | G36: ='Raw Data'!O7 -> 161.43 | H36: ='Raw Data'!P7 -> 161.47 | I36: ='Raw Data'!Q7 -> 161.52 | J36: 161.57 | K36: 161.62 | L36: 161.67 | M36: 161.72 | N36: 161.77
B37: Reserves & Surplus | C37: ='Raw Data'!K9 -> 15620.77 | D37: ='Raw Data'!L9 -> 17241.71 | E37: ='Raw Data'!M9 -> 19766.27 | F37: ='Raw Data'!N9 -> 22352.19 | G37: ='Raw Data'!O9 -> 24476.66 | H37: ='Raw Data'!P9 -> 27812.45 | I37: ='Raw Data'!Q9 -> 31937.72 | J37: =I37+J25-J29*'IS ,BS Assumptions'!I54 -> 31823.939 | K37: =J37+K25-K29*'IS ,BS Assumptions'!J54 -> 31560.46 | L37: =K37+L25-L29*'IS ,BS Assumptions'!K54 -> 31122.069 | M37: =L37+M25-M29*'IS ,BS Assumptions'!L54 -> 30583.047 | N37: =M37+N25-N29*'IS ,BS Assumptions'!M54 -> 30211.815
B38: Total Shareholders' Equity | C38: ='Raw Data'!K10 -> 15781.91 | D38: ='Raw Data'!L10 -> 17402.96 | E38: ='Raw Data'!M10 -> 19927.56 | F38: ='Raw Data'!N10 -> 22513.55 | G38: ='Raw Data'!O10 -> 24638.09 | H38: ='Raw Data'!P10 -> 27973.92 | I38: ='Raw Data'!Q10 -> 32099.24 | J38: =J36+J37 -> 31985.509 | K38: =K36+K37 -> 31722.08 | L38: =L36+L37 -> 31283.739 | M38: =M36+M37 -> 30744.767 | N38: =N36+N37 -> 30373.585
B39: Non-Current Liabilities
B40: Long-Term Borrowings | C40: ='Raw Data'!K12 -> 0 | D40: ='Raw Data'!L12 -> 0 | E40: ='Raw Data'!M12 -> 0 | F40: ='Raw Data'!N12 -> 0 | G40: ='Raw Data'!O12 -> 0 | H40: ='Raw Data'!P12 -> 0 | I40: ='Raw Data'!Q12 -> 0 | J40: 0 | K40: 0 | L40: 0 | M40: 0 | N40: 0
B41: Lease Liabilities (Non-Current) | C41: ='Raw Data'!K13 -> 0 | D41: ='Raw Data'!L13 -> 0 | E41: ='Raw Data'!M13 -> 29.46 | F41: ='Raw Data'!N13 -> 15.53 | G41: ='Raw Data'!O13 -> 35.53 | H41: ='Raw Data'!P13 -> 29.55 | I41: ='Raw Data'!Q13 -> 86.18 | J41: =I41*1.05 -> 90.489 | K41: =J41*1.05 -> 95.01345 | L41: =K41*1.05 -> 99.764123 | M41: =L41*1.05 -> 104.75233 | N41: =M41*1.05 -> 109.98995
B42: Deferred Tax Liabilities (Net) | C42: ='Raw Data'!K14 -> 42.84 | D42: ='Raw Data'!L14 -> 112.97 | E42: ='Raw Data'!M14 -> 104.91 | F42: ='Raw Data'!N14 -> 79.25 | G42: ='Raw Data'!O14 -> 36.13 | H42: ='Raw Data'!P14 -> 32.64 | I42: ='Raw Data'!Q14 -> 0 | J42: 0 | K42: 0 | L42: 0 | M42: 0 | N42: 0
B43: Other LT Liabilities & Provisions | C43: ='Raw Data'!K17+'Raw Data'!K18 -> 225.98 | D43: ='Raw Data'!L17+'Raw Data'!L18 -> 270.44 | E43: ='Raw Data'!M17+'Raw Data'!M18 -> 209.87 | F43: ='Raw Data'!N17+'Raw Data'!N18 -> 181.38 | G43: ='Raw Data'!O17+'Raw Data'!O18 -> 186.98 | H43: ='Raw Data'!P17+'Raw Data'!P18 -> 154.87 | I43: ='Raw Data'!Q17+'Raw Data'!Q18 -> 196.88 | J43: =I43*1.05 -> 206.724 | K43: =J43*1.05 -> 217.0602 | L43: =K43*1.05 -> 227.91321 | M43: =L43*1.05 -> 239.30887 | N43: =M43*1.05 -> 251.27431
B44: Total Non-Current Liabilities | C44: ='Raw Data'!K19 -> 268.82 | D44: ='Raw Data'!L19 -> 383.41 | E44: ='Raw Data'!M19 -> 344.24 | F44: ='Raw Data'!N19 -> 276.16 | G44: ='Raw Data'!O19 -> 258.64 | H44: ='Raw Data'!P19 -> 217.06 | I44: ='Raw Data'!Q19 -> 283.06 | J44: =J40+J41+J42+J43 -> 297.213 | K44: =K40+K41+K42+K43 -> 312.07365 | L44: =L40+L41+L42+L43 -> 327.67733 | M44: =M40+M41+M42+M43 -> 344.0612 | N44: =N40+N41+N42+N43 -> 361.26426
B45: Current Liabilities
B46: Short-Term Borrowings | C46: ='Raw Data'!K21 -> 0 | D46: ='Raw Data'!L21 -> 6.06 | E46: ='Raw Data'!M21 -> 0 | F46: ='Raw Data'!N21 -> 0 | G46: ='Raw Data'!O21 -> 0 | H46: ='Raw Data'!P21 -> 0 | I46: ='Raw Data'!Q21 -> 0 | J46: 0 | K46: 0 | L46: 0 | M46: 0 | N46: 0
B47: Trade Payables | C47: ='Raw Data'!K23 -> 1481.35 | D47: ='Raw Data'!L23 -> 1612.12 | E47: ='Raw Data'!M23 -> 1495.49 | F47: ='Raw Data'!N23 -> 1569.73 | G47: ='Raw Data'!O23 -> 1638.92 | H47: ='Raw Data'!P23 -> 1684.64 | I47: ='Raw Data'!Q23 -> 1883.71 | J47: ='IS ,BS Assumptions'!I51/365*J7 -> 2392.037 | K47: ='IS ,BS Assumptions'!J51/365*K7 -> 2572.5527 | L47: ='IS ,BS Assumptions'!K51/365*L7 -> 2738.8059 | M47: ='IS ,BS Assumptions'!L51/365*M7 -> 2890.7179 | N47: ='IS ,BS Assumptions'!M51/365*N7 -> 3088.6532
B48: Other Current Liabilities | C48: ='Raw Data'!K24 -> 406.59 | D48: ='Raw Data'!L24 -> 455.04 | E48: ='Raw Data'!M24 -> 548.66 | F48: ='Raw Data'!N24 -> 450.3 | G48: ='Raw Data'!O24 -> 399.52 | H48: ='Raw Data'!P24 -> 407.08 | I48: ='Raw Data'!Q24 -> 435.65 | J48: =I48*1.06 -> 461.789 | K48: =J48*1.06 -> 489.49634 | L48: =K48*1.06 -> 518.86612 | M48: =L48*1.06 -> 549.99809 | N48: =M48*1.06 -> 582.99797
B49: Short-Term Provisions | C49: ='Raw Data'!K25 -> 480.14 | D49: ='Raw Data'!L25 -> 546.07 | E49: ='Raw Data'!M25 -> 625.13 | F49: ='Raw Data'!N25 -> 631.39 | G49: ='Raw Data'!O25 -> 646.74 | H49: ='Raw Data'!P25 -> 754.53 | I49: ='Raw Data'!Q25 -> 832.86 | J49: =I49*1.06 -> 882.8316 | K49: =J49*1.06 -> 935.8015 | L49: =K49*1.06 -> 991.94959 | M49: =L49*1.06 -> 1051.4666 | N49: =M49*1.06 -> 1114.5546
B50: Total Current Liabilities | C50: ='Raw Data'!K26 -> 2368.08 | D50: ='Raw Data'!L26 -> 2619.29 | E50: ='Raw Data'!M26 -> 2691.94 | F50: ='Raw Data'!N26 -> 2659.34 | G50: ='Raw Data'!O26 -> 2699.74 | H50: ='Raw Data'!P26 -> 2862.25 | I50: ='Raw Data'!Q26 -> 3183.42 | J50: =J46+J47+J48+J49 -> 3736.6576 | K50: =K46+K47+K48+K49 -> 3997.8506 | L50: =L46+L47+L48+L49 -> 4249.6216 | M50: =M46+M47+M48+M49 -> 4492.1825 | N50: =N46+N47+N48+N49 -> 4786.2058
B52: TOTAL EQUITY & LIABILITIES | C52: ='Raw Data'!K28 -> 18418.81 | D52: ='Raw Data'!L28 -> 20405.66 | E52: ='Raw Data'!M28 -> 22963.74 | F52: ='Raw Data'!N28 -> 25449.05 | G52: ='Raw Data'!O28 -> 27596.47 | H52: ='Raw Data'!P28 -> 31053.23 | I52: ='Raw Data'!Q28 -> 35565.72 | J52: =J38+J44+J50 -> 36019.379 | K52: =K38+K44+K50 -> 36032.004 | L52: =L38+L44+L50 -> 35861.038 | M52: =M38+M44+M50 -> 35581.011 | N52: =N38+N44+N50 -> 35521.055
B54: BALANCE SHEET – ASSETS
...

Sheet PPE Schedule
B1: CIPLA LIMITED – PPE SCHEDULE
B4: Particulars | C4: 2019 Actual | D4: 2020 Actual | E4: 2021 Actual | F4: 2022 Actual | G4: 2023 Actual | H4: 2024 Actual | I4: 2025 Actual | J4: 2026 Forecast | K4: 2027 Forecast | L4: 2028 Forecast | M4: 2029 Forecast | N4: 2030 Forecast
B5: Revenue from Operations (Reference) | C5: ='Financial Statements'!C7 -> 12374.01 | D5: ='Financial Statements'!D7 -> 12659.15 | E5: ='Financial Statements'!E7 -> 11302.71 | F5: ='Financial Statements'!F7 -> 13091.79 | G5: ='Financial Statements'!G7 -> 14345.34 | H5: ='Financial Statements'!H7 -> 16574.34 | I5: ='Financial Statements'!I7 -> 19044.85 | J5: ='Financial Statements'!J7 -> 20568.438 | ... N5: ='Financial Statements'!N7 -> 27983.133
B7: Opening Net PPE (Tangible Assets) | C7: 4212 | D7: ='Financial Statements'!C56 -> 4424.79 | E7: ='Financial Statements'!D56 -> 4344.27 | F7: ='Financial Statements'!E56 -> 4297.77 | G7: ='Financial Statements'!F56 -> 4114.25 | H7: ='Financial Statements'!G56 -> 4251.53 | I7: ='Financial Statements'!H56 -> 4273.41 | J7: =I10 -> 4403.16 | K7: =J10 -> 4459.5682 | L7: =K10 -> 4605.1946 | M7: =L10 -> 4807.0564 | N7: =M10 -> 5075.3129
B8: Capital Expenditure – Actuals from Cash Flow Statement | Forecast = Capex % × Revenue | C8: =-'Raw Data'!B109 -> 312.05 | D8: =-'Raw Data'!C109 -> 449.71 | E8: =-'Raw Data'!D109 -> 516.97 | F8: =-'Raw Data'!E109 -> 331.68 | G8: =-'Raw Data'!F109 -> 684.15 | H8: =-'Raw Data'!G109 -> 682.71 | I8: =-'Raw Data'!H109 -> 728.68 | J8: ='IS ,BS Assumptions'!I52*J5 -> 760.91385 | K8: ='IS ,BS Assumptions'!J52*K5 -> 859.15732 | L8: ='IS ,BS Assumptions'!K52*L5 -> 938.69285 | M8: ='IS ,BS Assumptions'!L52*M5 -> 989.31504 | N8: ='IS ,BS Assumptions'!M52*N5 -> 1119.8186
B9: Less: Depreciation & Amortisation | C9: ='Raw Data'!B71 -> 569.72 | D9: ='Raw Data'!C71 -> 599.78 | E9: ='Raw Data'!D71 -> 468.62 | F9: ='Raw Data'!E71 -> 460.01 | G9: ='Raw Data'!F71 -> 595.91 | H9: ='Raw Data'!G71 -> 587.59 | I9: ='Raw Data'!H71 -> 573.89 | J9: =J7*J11 -> 704.5056 | K9: =K7*K11 -> 713.53092 | L9: =L7*L11 -> 736.83114 | M9: =M7*M11 -> 721.05845 | N9: =N7*N11 -> 761.29694
B10: Closing Net PPE (Tangible) | C10: ='Financial Statements'!C56 -> 4424.79 | D10: ='Financial Statements'!D56 -> 4344.27 | E10: ='Financial Statements'!E56 -> 4297.77 | F10: ='Financial Statements'!F56 -> 4114.25 | G10: ='Financial Statements'!G56 -> 4251.53 | H10: ='Financial Statements'!H56 -> 4273.41 | I10: ='Financial Statements'!I56 -> 4403.16 | J10: =J7+J8-J9 -> 4459.5682 | K10: =K7+K8-K9 -> 4605.1946 | L10: =L7+L8-L9 -> 4807.0564 | M10: =M7+M8-M9 -> 5075.3129 | N10: =N7+N8-N9 -> 5433.8346
B11: Depreciation Rate % of Opening PPE | C11: N/A | D11: ='Raw Data'!C71/'Raw Data'!B31 -> 2.2639188 | E11: ='Raw Data'!D71/'Raw Data'!C31 -> 1.8453239 | F11: ='Raw Data'!E71/'Raw Data'!D31 -> 1.9609941 | G11: ='Raw Data'!F71/'Raw Data'!E31 -> 2.4069392 | H11: ='Raw Data'!G71/'Raw Data'!F31 -> 2.2857198 | I11: ='Raw Data'!H71/'Raw Data'!G31 -> 2.1125304 | J11: 0.16 | K11: 0.16 | L11: 0.16 | M11: 0.15 | N11: 0.15
B12: Forecast Depreciation - Linked to Assumptions Sheet | J12: =J9 -> 704.5056 | K12: =K9 -> 713.53092 | L12: =L9 -> 736.83114 | M12: =M9 -> 721.05845 | N12: =N9 -> 761.29694
B13: Capex % of Revenue (Computed) | C13: =C8/C5 -> 0.025218179 | D13: =D8/D5 -> 0.035524502 | E13: =E8/E5 -> 0.045738588 | F13: =F8/F5 -> 0.025334962 | G13: =G8/G5 -> 0.047691445 | H13: =H8/H5 -> 0.04119078 | I13: =I8/I5 -> 0.038261262 | J13: =J8/J5 -> 0.036994246 | ... N13: =N8/N5 -> 0.040017629

Sheet Beta
A1: BETA CALCULATION
A3: CIPLA LTD. | E3: BSE SENSEX | I3: BETA : Market Risk
A4: Date | B4: Close Price | C4: Return % | E4: Date | F4: SENSEX | G4: Return % | I4: 10 Year Beta Computation
A5: 42370 | B5: 654.7 | E5: 42370 | F5: 26160.9
A6: 42373 | B6: 645.55 | C6: =LN(B6/B5) -> -0.014074449 | E6: 42373 | F6: 25623.35 | G6: =LN(F6/F5) -> -0.020761885 | I6: Using SLOPE Function | J6: =SLOPE(C6:C2482,G6:G2482) -> 0.44183817
A7: 42374 | B7: 641.15 | C7: =LN(B7/B6) -> -0.0068392277 | E7: 42374 | F7: 25580.34 | G7: =LN(F7/F6) -> -0.0016799574
A8: 42375 | B8: 652.4 | C8: =LN(B8/B7) -> 0.017394432 | E8: 42375 | F8: 25406.33 | G8: =LN(F8/F7) -> -0.0068257321
A9: 42376 | B9: 639.15 | C9: =LN(B9/B8) -> -0.020518702 | E9: 42376 | F9: 24851.83 | G9: =LN(F9/F8) -> -0.022066964
A10: 42377 | B10: 622.45 | C10: =LN(B10/B9) -> -0.026475865 | E10: 42377 | F10: 24934.33 | G10: =LN(F10/F9) -> 0.0033141771 | I10: Performance VS Market
A11: 42380 | B11: 610.25 | C11: =LN(B11/B10) -> -0.019794595 | E11: 42380 | F11: 24825.04 | G11: =LN(F11/F10) -> -0.0043927476
A12: 42381 | B12: 611.65 | C12: =LN(B12/B11) -> 0.0022915142 | E12: 42381 | F12: 24682.03 | G12: =LN(F12/F11) -> -0.0057773727 | I12: Cipla Ltd. | J12: =AVERAGE(C6:C2482) -> 0.00033761957
